<?xml version="1.0"?>
<sdf version="1.9">
  <model name="diffbot" canonical_link="base_link">
    <self_collide>false</self_collide>
    <allow_auto_disable>false</allow_auto_disable>

    <link name="base_link">
      <pose>0 0 0.25 0 0 0</pose>
      <inertial>
        <!-- Keep the center of mass below the wheel axle to suppress chassis
             pitch and roll during acceleration and braking. -->
        <pose>0 0 -0.12 0 0 0</pose>
        <mass>15.0</mass>
        <inertia>
          <ixx>1.50</ixx><iyy>1.50</iyy><izz>0.9250</izz>
          <ixy>0</ixy><ixz>0</ixz><iyz>0</iyz>
        </inertia>
      </inertial>
      <collision name="base_collision">
        <geometry><box><size>0.70 0.50 0.20</size></box></geometry>
      </collision>
      <visual name="base_visual">
        <geometry><box><size>0.70 0.50 0.20</size></box></geometry>
        <material>
          <ambient>0.15 0.25 0.65 1</ambient>
          <diffuse>0.15 0.25 0.65 1</diffuse>
        </material>
      </visual>
      <sensor name="imu" type="imu">
        <always_on>true</always_on>
        <update_rate>200</update_rate>
        <enable_metrics>true</enable_metrics>
      </sensor>
    </link>

    <link name="left_wheel">
      <!-- Keep the link / joint frame aligned with the chassis. Rotate only
           the cylinder geometry so the revolute Y axis remains the axle. -->
      <pose>0 0.29 0.15 0 0 0</pose>
      <inertial>
        <mass>1.0</mass>
        <inertia>
          <ixx>0.0062</ixx><iyy>0.0113</iyy><izz>0.0062</izz>
          <ixy>0</ixy><ixz>0</ixz><iyz>0</iyz>
        </inertia>
      </inertial>
      <collision name="collision">
        <pose>0 0 0 1.570796 0 0</pose>
        <geometry><cylinder><radius>0.15</radius><length>0.08</length></cylinder></geometry>
        <surface>
          <friction>
            <ode><mu>1.2</mu><mu2>1.2</mu2></ode>
          </friction>
        </surface>
      </collision>
      <visual name="visual">
        <pose>0 0 0 1.570796 0 0</pose>
        <geometry><cylinder><radius>0.15</radius><length>0.08</length></cylinder></geometry>
        <material><ambient>0.03 0.03 0.03 1</ambient><diffuse>0.03 0.03 0.03 1</diffuse></material>
      </visual>
    </link>

    <link name="right_wheel">
      <pose>0 -0.29 0.15 0 0 0</pose>
      <inertial>
        <mass>1.0</mass>
        <inertia>
          <ixx>0.0062</ixx><iyy>0.0113</iyy><izz>0.0062</izz>
          <ixy>0</ixy><ixz>0</ixz><iyz>0</iyz>
        </inertia>
      </inertial>
      <collision name="collision">
        <pose>0 0 0 1.570796 0 0</pose>
        <geometry><cylinder><radius>0.15</radius><length>0.08</length></cylinder></geometry>
        <surface>
          <friction>
            <ode><mu>1.2</mu><mu2>1.2</mu2></ode>
          </friction>
        </surface>
      </collision>
      <visual name="visual">
        <pose>0 0 0 1.570796 0 0</pose>
        <geometry><cylinder><radius>0.15</radius><length>0.08</length></cylinder></geometry>
        <material><ambient>0.03 0.03 0.03 1</ambient><diffuse>0.03 0.03 0.03 1</diffuse></material>
      </visual>
    </link>

    <link name="rear_caster">
      <pose>-0.27 0 0.08 0 0 0</pose>
      <inertial>
        <mass>0.2</mass>
        <inertia>
          <ixx>0.0005</ixx><iyy>0.0005</iyy><izz>0.0005</izz>
          <ixy>0</ixy><ixz>0</ixz><iyz>0</iyz>
        </inertia>
      </inertial>
      <collision name="collision">
        <geometry><sphere><radius>0.08</radius></sphere></geometry>
        <surface>
          <friction>
            <ode><mu>0.02</mu><mu2>0.02</mu2></ode>
          </friction>
        </surface>
      </collision>
      <visual name="visual">
        <geometry><sphere><radius>0.08</radius></sphere></geometry>
        <material><ambient>0.15 0.15 0.15 1</ambient><diffuse>0.15 0.15 0.15 1</diffuse></material>
      </visual>
    </link>

    <!-- A matching front skid prevents forward pitching under braking. Its
         very low friction lets the differential drive turn without binding. -->
    <link name="front_caster">
      <pose>0.27 0 0.08 0 0 0</pose>
      <inertial>
        <mass>0.2</mass>
        <inertia>
          <ixx>0.0005</ixx><iyy>0.0005</iyy><izz>0.0005</izz>
          <ixy>0</ixy><ixz>0</ixz><iyz>0</iyz>
        </inertia>
      </inertial>
      <collision name="collision">
        <geometry><sphere><radius>0.08</radius></sphere></geometry>
        <surface>
          <friction>
            <ode><mu>0.02</mu><mu2>0.02</mu2></ode>
          </friction>
        </surface>
      </collision>
      <visual name="visual">
        <geometry><sphere><radius>0.08</radius></sphere></geometry>
        <material><ambient>0.15 0.15 0.15 1</ambient><diffuse>0.15 0.15 0.15 1</diffuse></material>
      </visual>
    </link>

    <link name="lidar_link">
      <pose>0 0 0.75 0 0 0</pose>
      <inertial>
        <mass>1.0</mass>
        <inertia>
          <ixx>0.0055</ixx><iyy>0.0055</iyy><izz>0.0072</izz>
          <ixy>0</ixy><ixz>0</ixz><iyz>0</iyz>
        </inertia>
      </inertial>
      <collision name="collision">
        <geometry><cylinder><radius>0.12</radius><length>0.15</length></cylinder></geometry>
      </collision>
      <visual name="visual">
        <geometry><cylinder><radius>0.12</radius><length>0.15</length></cylinder></geometry>
        <material><ambient>0.1 0.1 0.1 1</ambient><diffuse>0.1 0.1 0.1 1</diffuse></material>
      </visual>

      <sensor name="lidar" type="gpu_lidar">
        <always_on>true</always_on>
        <update_rate>10</update_rate>
        <visualize>false</visualize>
        <ray>
          <scan>
            <horizontal>
              <samples>720</samples>
              <resolution>1</resolution>
              <min_angle>-3.14159265</min_angle>
              <max_angle>3.14159265</max_angle>
            </horizontal>
            <vertical>
              <samples>16</samples>
              <resolution>1</resolution>
              <min_angle>-0.261799</min_angle>
              <max_angle>0.261799</max_angle>
            </vertical>
          </scan>
          <range>
            <min>0.30</min>
            <max>50.0</max>
            <resolution>0.01</resolution>
          </range>
          <noise>
            <type>gaussian</type>
            <mean>0.0</mean>
            <stddev>0.01</stddev>
          </noise>
        </ray>
      </sensor>
    </link>

    <joint name="left_wheel_joint" type="revolute">
      <parent>base_link</parent>
      <child>left_wheel</child>
      <axis>
        <xyz>0 1 0</xyz>
        <limit><lower>-1e16</lower><upper>1e16</upper></limit>
        <dynamics><damping>0.05</damping><friction>0.01</friction></dynamics>
      </axis>
    </joint>

    <joint name="right_wheel_joint" type="revolute">
      <parent>base_link</parent>
      <child>right_wheel</child>
      <axis>
        <xyz>0 1 0</xyz>
        <limit><lower>-1e16</lower><upper>1e16</upper></limit>
        <dynamics><damping>0.05</damping><friction>0.01</friction></dynamics>
      </axis>
    </joint>

    <!-- The caster is a low-friction fixed skid contact. A free ball joint on
         a perfectly spherical link is underconstrained and can destabilize
         the small differential-drive chassis in DART. -->
    <joint name="rear_caster_joint" type="fixed">
      <parent>base_link</parent>
      <child>rear_caster</child>
    </joint>

    <joint name="front_caster_joint" type="fixed">
      <parent>base_link</parent>
      <child>front_caster</child>
    </joint>

    <joint name="lidar_joint" type="fixed">
      <parent>base_link</parent>
      <child>lidar_link</child>
    </joint>

    <plugin filename="gz-sim-diff-drive-system" name="gz::sim::systems::DiffDrive">
      <left_joint>left_wheel_joint</left_joint>
      <right_joint>right_wheel_joint</right_joint>
      <wheel_separation>0.58</wheel_separation>
      <wheel_radius>0.15</wheel_radius>
      <odom_publish_frequency>50</odom_publish_frequency>
      <max_linear_velocity>5.0</max_linear_velocity>
      <min_linear_velocity>-5.0</min_linear_velocity>
      <max_angular_velocity>1.5</max_angular_velocity>
      <min_angular_velocity>-1.5</min_angular_velocity>
      <max_linear_acceleration>0.6</max_linear_acceleration>
      <max_linear_deceleration>5.0</max_linear_deceleration>
      <max_angular_acceleration>1.0</max_angular_acceleration>
      <max_angular_deceleration>5.0</max_angular_deceleration>
    </plugin>

    <plugin filename="gz-sim-joint-state-publisher-system" name="gz::sim::systems::JointStatePublisher"/>

    <plugin filename="gz-sim-pose-publisher-system" name="gz::sim::systems::PosePublisher">
      <publish_model_pose>true</publish_model_pose>
      <publish_link_pose>false</publish_link_pose>
      <publish_collision_pose>false</publish_collision_pose>
      <publish_visual_pose>false</publish_visual_pose>
      <publish_sensor_pose>false</publish_sensor_pose>
      <publish_nested_model_pose>false</publish_nested_model_pose>
      <use_pose_vector_msg>true</use_pose_vector_msg>
      <static_publisher>false</static_publisher>
      <update_frequency>30</update_frequency>
    </plugin>

  </model>
</sdf>
